<?xml version="1.0" encoding="utf-8"?>
<!-- =================================================================================== -->
<!--   Copyright 2019 ANYbotics, https://www.anybotics.com                               -->
<!-- =================================================================================== -->
<!-- This file contains the description of the ANYmal B robot. -->
<?xml version="1.0" ?>
<robot name="anymal_arm">

    <!--
      Material colors
    -->

    <!-- Basic colors -->
    <material name="black">
        <color rgba="0.0 0.0 0.0 1.0"/>
    </material>
    <material name="blue">
        <color rgba="0.0 0.0 0.8 1.0"/>
    </material>
    <material name="green">
        <color rgba="0.0 0.8 0.0 1.0"/>
    </material>
    <material name="grey">
        <color rgba="0.2 0.2 0.2 1.0"/>
    </material>
    <material name="light_grey">
        <color rgba="0.4 0.4 0.4 1.0"/>
    </material>
    <material name="red">
        <color rgba="0.8 0.0 0.0 1.0"/>
    </material>
    <material name="white">
        <color rgba="1.0 1.0 1.0 1.0"/>
    </material>

    <!-- Material for the visual primitives -->
    <material name="anymal_material">
        <color rgba="0.7 0.7 0.7 1.0"/>
    </material>

    <!--
      Base
    -->

    <!-- Base link -->
    <link name="base">
        <visual>
            <origin rpy="0 0 0" xyz="0 0 0"/>
            <geometry>
                <mesh filename="../meshes/anymal_base.dae" scale="0.001 0.001 0.001"/>
            </geometry>
        </visual>
        <!-- Main Body -->
        <collision>
            <origin rpy="0 0 0" xyz="0 0 0.08"/>
            <geometry>
                <box size="0.531 0.27 0.24"/>
            </geometry>
        </collision>
    </link>
    <!-- Fixed joint to add dummy inertia link -->
    <joint name="base_to_base_inertia" type="fixed">
        <parent link="base"/>
        <child link="base_inertia"/>
        <origin rpy="0 0 0" xyz="0 0 0"/>
    </joint>
    <!-- Dummy inertia link, because KDL cannot have inertia on the base link -->
    <link name="base_inertia">
        <inertial>
            <origin rpy="0 0 0" xyz="-0.001960558279 -0.001413217745 0.050207125344"/>
            <mass value="16.793507758"/>
            <inertia ixx="0.217391101503" ixy="-0.00132873239126" ixz="-0.00228200226173" iyy="0.639432546734" iyz="-0.00138078263145" izz="0.62414077654"/>
        </inertial>
    </link>

    <!--
      Left-Fore leg
    -->

    <!-- high link -->
    <link name="LF_HIP">
        <visual>
            <origin rpy="0 0 0.0" xyz="0 0 0"/>
            <geometry>
                <mesh filename="../meshes/anymal_hip_l.dae" scale="0.001 0.001 0.001"/>
            </geometry>
        </visual>
        <inertial>
            <origin rpy="0 0 0" xyz="0.064516258147 -0.003787101702 -0.000152184388"/>
            <mass value="1.42462064"/>
            <inertia ixx="0.00243023349564" ixy="-1.53023971e-05" ixz="-2.1819095354e-05" iyy="0.00230257239103" iyz="2.6473021273e-05" izz="0.0019806759227"/>
        </inertial>
    </link>
    <!-- Hip joint -->
    <joint name="LF_HAA" type="revolute">
        <parent link="base"/>
        <child link="LF_HIP"/>
        <origin xyz="0.277 0.116 0.0"/>
        <axis xyz="1 0 0"/>
        <limit effort="80" lower="-6.28" upper="6.28" velocity="15"/>
        <dynamics damping="0.0" friction="0.0"/>
    </joint>

    <!-- Thigh link -->
    <link name="LF_THIGH">
        <visual>
            <origin rpy="0 0 0.0" xyz="0 0 0"/>
            <geometry>
                <mesh filename="../meshes/anymal_thigh_l.dae" scale="0.001 0.001 0.001"/>
            </geometry>
        </visual>
        <collision>
            <!-- KFE actuator -->
            <origin rpy="1.57079632679 0 0" xyz="0.0 0.07205 -0.25"/>
            <geometry>
                <cylinder length="0.11" radius="0.06"/>
            </geometry>
        </collision>
        <inertial>
            <origin rpy="0 0 0" xyz="-0.003897968082 0.054226618537 -0.214583373795"/>
            <mass value="1.634976467"/>
            <inertia ixx="0.0120367944369" ixy="6.762065206e-05" ixz="0.000287806340448" iyy="0.0120643637939" iyz="-0.00140610131218" izz="0.00249422574881"/>
        </inertial>
    </link>
    <!-- Thigh joint -->
    <joint name="LF_HFE" type="revolute">
        <parent link="LF_HIP"/>
        <child link="LF_THIGH"/>
        <origin xyz="0.0635                    0.041                    0.0"/>
        <axis xyz="0 1 0"/>
        <limit effort="80" lower="-6.28" upper="6.28" velocity="15"/>
        <dynamics damping="0.0" friction="0.0"/>
    </joint>

    <!-- Shank link -->
    <link name="LF_SHANK">
        <visual>
            <origin rpy="0 0 0.0" xyz="0 0 0"/>
            <geometry>
                <mesh filename="../meshes/anymal_shank_l.dae" scale="0.001 0.001 0.001"/>
            </geometry>
        </visual>
        <inertial>
            <origin rpy="0 0 0" xyz="0.030816858139 -0.004617229294 0.000893125713"/>
            <mass value="0.207204302"/>
            <inertia ixx="0.0002104880248" ixy="-5.6750980345e-05" ixz="1.0127699391e-05" iyy="0.000676270210023" iyz="-8.22869024e-07" izz="0.000545032674924"/>
        </inertial>
    </link>
    <!-- Shank joint -->
    <joint name="LF_KFE" type="revolute">
        <parent link="LF_THIGH"/>
        <child link="LF_SHANK"/>
        <origin xyz="0.0 0.109 -0.25"/>
        <axis xyz="0 1 0"/>
        <limit effort="80" lower="-6.28" upper="6.28" velocity="15"/>
        <dynamics damping="0.0" friction="0.0"/>
    </joint>
    <!-- Shank to Adapter joint -->
    <joint name="LF_SHANK_TO_ADAPTER" type="fixed">
        <parent link="LF_SHANK"/>
        <child link="LF_ADAPTER"/>
        <origin rpy="0.0 0.0 0.0" xyz="0.1 -0.02 0.0"/>
    </joint>

    <!-- Adapter link -->
    <link name="LF_ADAPTER">
        <visual>
            <origin rpy="0 0 0.0" xyz="0 0 0.032"/>
            <geometry>
                <mesh filename="../meshes/anymal_foot.dae" scale="0.001 0.001 0.001"/>
            </geometry>
        </visual>
        <collision>
            <origin rpy="0 0 0" xyz="0 0 -0.160625"/>
            <geometry>
                <cylinder length="0.22125" radius="0.015"/>
            </geometry>
        </collision>
        <inertial>
            <origin rpy="0 0 0" xyz="-8.66e-10 -1.472e-09 -0.244345749188"/>
            <mass value="0.140170767"/>
            <inertia ixx="0.00159938741862" ixy="-9.32e-13" ixz="1.039e-11" iyy="0.00159938741932" iyz="1.7563e-11" izz="5.4423177329e-05"/>
        </inertial>
    </link>
    <!-- Adapter to Foot joint -->
    <joint name="LF_ADAPTER_TO_FOOT" type="fixed">
        <parent link="LF_ADAPTER"/>
        <child link="LF_FOOT"/>
        <origin rpy="0.0 0.0 0.0" xyz="0.0 0.0 -0.32125"/>
    </joint>

    <!-- Foot link -->
    <link name="LF_FOOT">
        <collision>
            <origin xyz="0 0 0.02325"/>
            <geometry>
                <sphere radius="0.035"/>
            </geometry>
        </collision>
    </link>

    <!--
      Right-Hind leg
    -->

    <!-- Hip link -->
    <link name="RH_HIP">
        <visual>
            <origin rpy="0 0 -3.14159265359" xyz="0 0 0"/>
            <geometry>
                <mesh filename="../meshes/anymal_hip_l.dae" scale="0.001 0.001 0.001"/>
            </geometry>
        </visual>
        <inertial>
            <origin rpy="0 0 0" xyz="-0.064516258147 0.003787101702 -0.000152184388"/>
            <mass value="1.42462064"/>
            <inertia ixx="0.00243023349564" ixy="-1.53023971e-05" ixz="2.1819095354e-05" iyy="0.00230257239103" iyz="-2.6473021273e-05" izz="0.0019806759227"/>
        </inertial>
    </link>
    <!-- Hip joint -->
    <joint name="RH_HAA" type="revolute">
        <parent link="base"/>
        <child link="RH_HIP"/>
        <origin xyz="-0.277 -0.116 0.0"/>
        <axis xyz="1 0 0"/>
        <limit effort="80" lower="-6.28" upper="6.28" velocity="15"/>
        <dynamics damping="0.0" friction="0.0"/>
    </joint>

    <!-- Thigh link -->
    <link name="RH_THIGH">
        <visual>
            <origin rpy="0 0 -3.14159265359" xyz="0 0 0"/>
            <geometry>
                <mesh filename="../meshes/anymal_thigh_l.dae" scale="0.001 0.001 0.001"/>
            </geometry>
        </visual>
        <collision>
            <!-- KFE actuator -->
            <origin rpy="1.57079632679 0 0" xyz="0.0 -0.07205 -0.25"/>
            <geometry>
                <cylinder length="0.11" radius="0.06"/>
            </geometry>
        </collision>
        <inertial>
            <origin rpy="0 0 0" xyz="0.003897968082 -0.054226618537 -0.214583373795"/>
            <mass value="1.634976467"/>
            <inertia ixx="0.0120367944369" ixy="6.762065206e-05" ixz="-0.000287806340448" iyy="0.0120643637939" iyz="0.00140610131218" izz="0.00249422574881"/>
        </inertial>
    </link>
    <!-- Thigh joint -->
    <joint name="RH_HFE" type="revolute">
        <parent link="RH_HIP"/>
        <child link="RH_THIGH"/>
        <origin xyz="-0.0635 -0.041 0.0"/>
        <axis xyz="0 1 0"/>
        <limit effort="80" lower="-6.28" upper="6.28" velocity="15"/>
        <dynamics damping="0.0" friction="0.0"/>
    </joint>

    <!-- Shank link -->
    <link name="RH_SHANK">
        <visual>
            <origin rpy="0 0 -3.14159265359" xyz="0 0 0"/>
            <geometry>
                <mesh filename="../meshes/anymal_shank_l.dae" scale="0.001 0.001 0.001"/>
            </geometry>
        </visual>
        <inertial>
            <origin rpy="0 0 0" xyz="-0.030816858139 0.004617229294 0.000893125713"/>
            <mass value="0.207204302"/>
            <inertia ixx="0.0002104880248" ixy="-5.6750980345e-05" ixz="-1.0127699391e-05" iyy="0.000676270210023" iyz="8.22869024e-07" izz="0.000545032674924"/>
        </inertial>
    </link>
    <!-- Shank joint -->
    <joint name="RH_KFE" type="revolute">
        <parent link="RH_THIGH"/>
        <child link="RH_SHANK"/>
        <origin xyz="-0.0 -0.109 -0.25"/>
        <axis xyz="0 1 0"/>
        <limit effort="80" lower="-6.28" upper="6.28" velocity="15"/>
        <dynamics damping="0.0" friction="0.0"/>
    </joint>
    <!-- Shank to Adapter joint -->
    <joint name="RH_SHANK_TO_ADAPTER" type="fixed">
        <parent link="RH_SHANK"/>
        <child link="RH_ADAPTER"/>
        <origin rpy="-0.0 -0.0 0.0" xyz="-0.1 0.02 0.0"/>
    </joint>

    <!-- Adapter link -->
    <link name="RH_ADAPTER">
        <visual>
            <origin rpy="0 0 -3.14159265359" xyz="0 0 0.032"/>
            <geometry>
                <mesh filename="../meshes/anymal_foot.dae" scale="0.001 0.001 0.001"/>
            </geometry>
        </visual>
        <collision>
            <origin rpy="0 0 0" xyz="0 0 -0.160625"/>
            <geometry>
                <cylinder length="0.22125" radius="0.015"/>
            </geometry>
        </collision>
        <inertial>
            <origin rpy="0 0 0" xyz="-8.66e-10 -1.472e-09 -0.244345749188"/>
            <mass value="0.140170767"/>
            <inertia ixx="0.00159938741862" ixy="-9.32e-13" ixz="1.039e-11" iyy="0.00159938741932" iyz="1.7563e-11" izz="5.4423177329e-05"/>
        </inertial>
    </link>
    <!-- Adapter to Foot joint -->
    <joint name="RH_ADAPTER_TO_FOOT" type="fixed">
        <parent link="RH_ADAPTER"/>
        <child link="RH_FOOT"/>
        <origin rpy="-0.0 -0.0 0.0" xyz="-0.0 -0.0 -0.32125"/>
    </joint>

    <!-- Foot link -->
    <link name="RH_FOOT">
        <collision>
            <origin xyz="0 0 0.02325"/>
            <geometry>
                <sphere radius="0.035"/>
            </geometry>
        </collision>
    </link>

    <!--
      Right-Fore leg
    -->

    <!-- Hip link -->
    <link name="RF_HIP">
        <visual>
            <origin rpy="0 0 0.0" xyz="0 0 0"/>
            <geometry>
                <mesh filename="../meshes/anymal_hip_r.dae" scale="0.001 0.001 0.001"/>
            </geometry>
        </visual>
        <inertial>
            <origin rpy="0 0 0" xyz="0.064516258147 0.003787101702 -0.000152184388"/>
            <mass value="1.42462064"/>
            <inertia ixx="0.00243023349564" ixy="1.53023971e-05" ixz="-2.1819095354e-05" iyy="0.00230257239103" iyz="-2.6473021273e-05" izz="0.0019806759227"/>
        </inertial>
    </link>
    <!-- Hip joint -->
    <joint name="RF_HAA" type="revolute">
        <parent link="base"/>
        <child link="RF_HIP"/>
        <origin xyz="0.277 -0.116 0.0"/>
        <axis xyz="1 0 0"/>
        <limit effort="80" lower="-6.28" upper="6.28" velocity="15"/>
        <dynamics damping="0.0" friction="0.0"/>
    </joint>

    <!-- Thigh link -->
    <link name="RF_THIGH">
        <visual>
            <origin rpy="0 0 0.0" xyz="0 0 0"/>
            <geometry>
                <mesh filename="../meshes/anymal_thigh_r.dae" scale="0.001 0.001 0.001"/>
            </geometry>
        </visual>
        <collision>
            <!-- KFE actuator -->
            <origin rpy="1.57079632679 0 0" xyz="0.0 -0.07205 -0.25"/>
            <geometry>
                <cylinder length="0.11" radius="0.06"/>
            </geometry>
        </collision>
        <inertial>
            <origin rpy="0 0 0" xyz="-0.003897968082 -0.054226618537 -0.214583373795"/>
            <mass value="1.634976467"/>
            <inertia ixx="0.0120367944369" ixy="-6.762065206e-05" ixz="0.000287806340448" iyy="0.0120643637939" iyz="0.00140610131218" izz="0.00249422574881"/>
        </inertial>
    </link>
    <!-- Thigh joint -->
    <joint name="RF_HFE" type="revolute">
        <parent link="RF_HIP"/>
        <child link="RF_THIGH"/>
        <origin xyz="0.0635                    -0.041                    0.0"/>
        <axis xyz="0 1 0"/>
        <limit effort="80" lower="-6.28" upper="6.28" velocity="15"/>
        <dynamics damping="0.0" friction="0.0"/>
    </joint>

    <!-- Shank link -->
    <link name="RF_SHANK">
        <visual>
            <origin rpy="0 0 0.0" xyz="0 0 0"/>
            <geometry>
                <mesh filename="../meshes/anymal_shank_r.dae" scale="0.001 0.001 0.001"/>
            </geometry>
        </visual>
        <inertial>
            <origin rpy="0 0 0" xyz="0.030816858139 0.004617229294 0.000893125713"/>
            <mass value="0.207204302"/>
            <inertia ixx="0.0002104880248" ixy="5.6750980345e-05" ixz="1.0127699391e-05" iyy="0.000676270210023" iyz="8.22869024e-07" izz="0.000545032674924"/>
        </inertial>
    </link>
    <!-- Shank joint -->
    <joint name="RF_KFE" type="revolute">
        <parent link="RF_THIGH"/>
        <child link="RF_SHANK"/>
        <origin xyz="0.0 -0.109 -0.25"/>
        <axis xyz="0 1 0"/>
        <limit effort="80" lower="-6.28" upper="6.28" velocity="15"/>
        <dynamics damping="0.0" friction="0.0"/>
    </joint>
    <!-- Shank to Adapter joint -->
    <joint name="RF_SHANK_TO_ADAPTER" type="fixed">
        <parent link="RF_SHANK"/>
        <child link="RF_ADAPTER"/>
        <origin rpy="-0.0 0.0 -0.0" xyz="0.1 0.02 0.0"/>
    </joint>

    <!-- Adapter link -->
    <link name="RF_ADAPTER">
        <visual>
            <origin rpy="0 0 0.0" xyz="0 0 0.032"/>
            <geometry>
                <mesh filename="../meshes/anymal_foot.dae" scale="0.001 0.001 0.001"/>
            </geometry>
        </visual>
        <collision>
            <origin rpy="0 0 0" xyz="0 0 -0.160625"/>
            <geometry>
                <cylinder length="0.22125" radius="0.015"/>
            </geometry>
        </collision>
        <inertial>
            <origin rpy="0 0 0" xyz="-8.66e-10 -1.472e-09 -0.244345749188"/>
            <mass value="0.140170767"/>
            <inertia ixx="0.00159938741862" ixy="-9.32e-13" ixz="1.039e-11" iyy="0.00159938741932" iyz="1.7563e-11" izz="5.4423177329e-05"/>
        </inertial>
    </link>
    <!-- Adapter to Foot joint -->
    <joint name="RF_ADAPTER_TO_FOOT" type="fixed">
        <parent link="RF_ADAPTER"/>
        <child link="RF_FOOT"/>
        <origin rpy="-0.0 0.0 -0.0" xyz="0.0 -0.0 -0.32125"/>
    </joint>

    <!-- Foot link -->
    <link name="RF_FOOT">
        <collision>
            <origin xyz="0 0 0.02325"/>
            <geometry>
                <sphere radius="0.035"/>
            </geometry>
        </collision>
    </link>


    <!--
      Left-Hind leg
    -->

    <!-- Hip link -->
    <link name="LH_HIP">
        <visual>
            <origin rpy="0 0 -3.14159265359" xyz="0 0 0"/>
            <geometry>
                <mesh filename="../meshes/anymal_hip_r.dae" scale="0.001 0.001 0.001"/>
            </geometry>
        </visual>
        <inertial>
            <origin rpy="0 0 0" xyz="-0.064516258147 -0.003787101702 -0.000152184388"/>
            <mass value="1.42462064"/>
            <inertia ixx="0.00243023349564" ixy="1.53023971e-05" ixz="2.1819095354e-05" iyy="0.00230257239103" iyz="2.6473021273e-05" izz="0.0019806759227"/>
        </inertial>
    </link>
    <!-- Hip joint -->
    <joint name="LH_HAA" type="revolute">
        <parent link="base"/>
        <child link="LH_HIP"/>
        <origin xyz="-0.277 0.116 0.0"/>
        <axis xyz="1 0 0"/>
        <limit effort="80" lower="-6.28" upper="6.28" velocity="15"/>
        <dynamics damping="0.0" friction="0.0"/>
    </joint>

    <!-- Thigh link -->
    <link name="LH_THIGH">
        <visual>
            <origin rpy="0 0 -3.14159265359" xyz="0 0 0"/>
            <geometry>
                <mesh filename="../meshes/anymal_thigh_r.dae" scale="0.001 0.001 0.001"/>
            </geometry>
        </visual>
        <collision>
            <!-- KFE actuator -->
            <origin rpy="1.57079632679 0 0" xyz="0.0 0.07205 -0.25"/>
            <geometry>
                <cylinder length="0.11" radius="0.06"/>
            </geometry>
        </collision>
        <inertial>
            <origin rpy="0 0 0" xyz="0.003897968082 0.054226618537 -0.214583373795"/>
            <mass value="1.634976467"/>
            <inertia ixx="0.0120367944369" ixy="-6.762065206e-05" ixz="-0.000287806340448" iyy="0.0120643637939" iyz="-0.00140610131218" izz="0.00249422574881"/>
        </inertial>
    </link>
    <!-- Thigh joint -->
    <joint name="LH_HFE" type="revolute">
        <parent link="LH_HIP"/>
        <child link="LH_THIGH"/>
        <origin xyz="-0.0635                    0.041                    0.0"/>
        <axis xyz="0 1 0"/>
        <limit effort="80" lower="-6.28" upper="6.28" velocity="15"/>
        <dynamics damping="0.0" friction="0.0"/>
    </joint>

    <!-- Shank link -->
    <link name="LH_SHANK">
        <visual>
            <origin rpy="0 0 -3.14159265359" xyz="0 0 0"/>
            <geometry>
                <mesh filename="../meshes/anymal_shank_r.dae" scale="0.001 0.001 0.001"/>
            </geometry>
        </visual>
        <inertial>
            <origin rpy="0 0 0" xyz="-0.030816858139 -0.004617229294 0.000893125713"/>
            <mass value="0.207204302"/>
            <inertia ixx="0.0002104880248" ixy="5.6750980345e-05" ixz="-1.0127699391e-05" iyy="0.000676270210023" iyz="-8.22869024e-07" izz="0.000545032674924"/>
        </inertial>
    </link>
    <!-- Shank joint -->
    <joint name="LH_KFE" type="revolute">
        <parent link="LH_THIGH"/>
        <child link="LH_SHANK"/>
        <origin xyz="-0.0 0.109 -0.25"/>
        <axis xyz="0 1 0"/>
        <limit effort="80" lower="-6.28" upper="6.28" velocity="15"/>
        <dynamics damping="0.0" friction="0.0"/>
    </joint>
    <!-- Shank to Adapter joint -->
    <joint name="LH_SHANK_TO_ADAPTER" type="fixed">
        <parent link="LH_SHANK"/>
        <child link="LH_ADAPTER"/>
        <origin rpy="0.0 -0.0 -0.0" xyz="-0.1 -0.02 0.0"/>
    </joint>

    <!-- Adapter link -->
    <link name="LH_ADAPTER">
        <visual>
            <origin rpy="0 0 -3.14159265359" xyz="0 0 0.032"/>
            <geometry>
                <mesh filename="../meshes/anymal_foot.dae" scale="0.001 0.001 0.001"/>
            </geometry>
        </visual>
        <collision>
            <origin rpy="0 0 0" xyz="0 0 -0.160625"/>
            <geometry>
                <cylinder length="0.22125" radius="0.015"/>
            </geometry>
        </collision>
        <inertial>
            <origin rpy="0 0 0" xyz="-8.66e-10 -1.472e-09 -0.244345749188"/>
            <mass value="0.140170767"/>
            <inertia ixx="0.00159938741862" ixy="-9.32e-13" ixz="1.039e-11" iyy="0.00159938741932" iyz="1.7563e-11" izz="5.4423177329e-05"/>
        </inertial>
    </link>
    <!-- Adapter to Foot joint -->
    <joint name="LH_ADAPTER_TO_FOOT" type="fixed">
        <parent link="LH_ADAPTER"/>
        <child link="LH_FOOT"/>
        <origin rpy="0.0 -0.0 -0.0" xyz="-0.0 0.0 -0.32125"/>
    </joint>

    <!-- Foot link -->
    <link name="LH_FOOT">
        <collision>
            <origin xyz="0 0 0.02325"/>
            <geometry>
                <sphere radius="0.035"/>
            </geometry>
        </collision>
    </link>


    <!--
        Kinova Part
    -->
    
    <!-- Base link -->
    <link name="kinova_link_base">
        <visual>
        <geometry>
            <mesh filename="../meshes/base.dae"/>
        </geometry>
        <material name="carbon_fiber">
            <color rgba="0.792156862745098 0.819607843137255 0.933333333333333 1"/>
        </material>
        </visual>
    </link>

    <joint name="kinova_joint_base" type="fixed">
        <parent link="base"/>
        <child link="kinova_link_base"/>
        <origin rpy="0 0 0" xyz="0.15 0 0.15"/>
    </joint>

    <!-- Fixed joint to add dummy inertia link -->
    <joint name="kinova_link_base_to_kinova_link_base_inertia" type="fixed">
        <parent link="kinova_link_base"/>
        <child link="kinova_link_base_inertia"/>
        <origin rpy="0 0 0" xyz="0 0 0"/>
    </joint>

    <!-- Dummy inertia link, because KDL cannot have inertia on the base link -->
    <link name="kinova_link_base_inertia">
        <inertial>
        <mass value="0.46784"/>
        <origin rpy="0 0 0" xyz="0 0 0.1255"/>
        <inertia ixx="0.000951270861568" ixy="0" ixz="0" iyy="0.000951270861568" iyz="0" izz="0.000374272"/>
        </inertial>
    </link>

    <link name="kinova_link_1">
        <visual>
        <geometry>
            <mesh filename="../meshes/shoulder.dae"/>
        </geometry>
        <material name="carbon_fiber">
            <color rgba="0.792156862745098 0.819607843137255 0.933333333333333 1"/>
        </material>
        </visual>
        <visual>
        <geometry>
            <mesh filename="../meshes/ring_big.STL"/>
        </geometry>
        </visual>
        <inertial>
        <mass value="0.7477"/>
        <origin xyz="0 -0.002 -0.0605"/>
        <inertia ixx="0.00152031725204" ixy="0" ixz="0" iyy="0.00152031725204" iyz="0" izz="0.00059816"/>
        </inertial>
    </link>

    <joint name="kinova_joint_1" type="revolute">
        <parent link="kinova_link_base"/>
        <child link="kinova_link_1"/>
        <axis xyz="0 0 1"/>
        <limit effort="30.5" lower="-62.8318530718" upper="62.8318530718" velocity="15"/>
        <origin rpy="0 3.14159265359 0" xyz="0 0 0.15675"/>
        <dynamics damping="0.0" friction="0.0"/>
    </joint>

    <link name="kinova_link_2">
        <visual>
        <geometry>
            <mesh filename="../meshes/arm.dae"/>
        </geometry>
        <material name="carbon_fiber">
            <color rgba="0.792156862745098 0.819607843137255 0.933333333333333 1"/>
        </material>
        </visual>
        <visual>
        <geometry>
            <mesh filename="../meshes/ring_big.STL"/>
        </geometry>
        </visual>
        <inertial>
        <mass value="0.99"/>
        <origin xyz="0 -0.2065 -0.01"/>
        <inertia ixx="0.010502207991" ixy="0" ixz="0" iyy="0.000792" iyz="0" izz="0.010502207991"/>
        </inertial>
    </link>

    <joint name="kinova_joint_2" type="revolute">
        <parent link="kinova_link_1"/>
        <child link="kinova_link_2"/>
        <axis xyz="0 0 1"/>
        <limit effort="30.5" lower="-62.8318530718" upper="62.8318530718" velocity="15"/>
        <!-- limit effort also defines torque limit and freeze controller gains -->
        <origin rpy="-1.57079632679 0 3.14159265359" xyz="0 0.0016 -0.11875"/>
        <dynamics damping="0.0" friction="0.0"/>
    </joint>

    <link name="kinova_link_3">
        <visual>
        <geometry>
            <mesh filename="../meshes/forearm.dae"/>
        </geometry>
        <material name="carbon_fiber">
            <color rgba="0.792156862745098 0.819607843137255 0.933333333333333 1"/>
        </material>
        </visual>
        <visual>
        <geometry>
            <mesh filename="../meshes/ring_big.STL"/>
        </geometry>
        </visual>
        <collision>
            <!-- KFE actuator -->
            <origin rpy="0 0 0" xyz="0.0 0 0"/>
            <geometry>
                <cylinder length="0.3" radius="0.05"/>
            </geometry>
        </collision>
        <inertial>
        <mass value="0.6763"/>
        <origin xyz="0 0.081 -0.0086"/>
        <inertia ixx="0.00142022431908" ixy="0" ixz="0" iyy="0.000304335" iyz="0" izz="0.00142022431908"/>
        </inertial>
    </link>

    <joint name="kinova_joint_3" type="revolute">
        <parent link="kinova_link_2"/>
        <child link="kinova_link_3"/>
        <axis xyz="0 0 1"/>
        <limit effort="30.5" lower="-62.8318530718" upper="62.8318530718" velocity="15"/>
        <!-- limit effort also defines torque limit and freeze controller gains -->
        <origin rpy="0 3.14159265359 0" xyz="0 -0.410 0"/>
        <dynamics damping="0.0" friction="0.0"/>
    </joint>

    <link name="kinova_link_4">
        <visual>
        <geometry>
            <mesh filename="../meshes/wrist_spherical_1.dae"/>
        </geometry>
        <material name="carbon_fiber">
            <color rgba="0.792156862745098 0.819607843137255 0.933333333333333 1"/>
        </material>
        </visual>
        <visual>
        <geometry>
            <mesh filename="../meshes/ring_small.STL"/>
        </geometry>
        </visual>
        --&gt;

        <inertial>
        <mass value="0.463"/>
        <origin xyz="0 0.0028848942 -0.0541932613"/>
        <inertia ixx="0.0004321316048" ixy="0" ixz="0" iyy="0.0004321316048" iyz="0" izz="9.26e-05"/>
        </inertial>
    </link>

    <joint name="kinova_joint_4" type="revolute">
        <parent link="kinova_link_3"/>
        <child link="kinova_link_4"/>
        <axis xyz="0 0 1"/>
        <limit effort="6.8" lower="-62.8318530718" upper="6.28318530718" velocity="15"/>
        <!-- limit effort also defines torque limit and freeze controller gains -->
        <origin rpy="-1.57079632679 0 3.14159265359" xyz="0 0.2073 -0.0114"/>
        <dynamics damping="0.0" friction="0.0"/>
    </joint>

    <link name="kinova_link_5">
        <visual>
        <geometry>
            <mesh filename="../meshes/wrist_spherical_2.dae"/>
        </geometry>
        <material name="carbon_fiber">
            <color rgba="0.792156862745098 0.819607843137255 0.933333333333333 1"/>
        </material>
        </visual>
        <visual>
        <geometry>
            <mesh filename="../meshes/ring_small.STL"/>
        </geometry>
        </visual>
        --&gt;
        <collision>
            <!-- KFE actuator -->
            <origin rpy="0 0 0" xyz="0.0 0 0"/>
            <geometry>
                <cylinder length="0.1" radius="0.07"/>
            </geometry>
        </collision>

        <inertial>
        <mass value="0.463"/>
        <origin xyz="0 0.0497208855 -0.0028562765"/>
        <inertia ixx="0.0004321316048" ixy="0" ixz="0" iyy="9.26e-05" iyz="0" izz="0.0004321316048"/>
        </inertial>
    </link>

    <joint name="kinova_joint_5" type="revolute">
        <parent link="kinova_link_4"/>
        <child link="kinova_link_5"/>
        <axis xyz="0 0 1"/>
        <limit effort="6.8" lower="-6.28318530718" upper="62.8318530718" velocity="15"/>
        <!-- limit effort also defines torque limit and freeze controller gains -->
        <origin rpy="1.57079632679 0 3.14159265359" xyz="0 0 -0.10375"/>
        <dynamics damping="0.0" friction="0.0"/>
    </joint>

    <link name="kinova_link_6">
        <visual>
        <geometry>
            <mesh filename="../meshes/hand_3finger.dae"/>
        </geometry>
        <material name="carbon_fiber">
            <color rgba="0.792156862745098 0.819607843137255 0.933333333333333 1"/>
        </material>
        </visual>
        <visual>
        <geometry>
            <mesh filename="../meshes/ring_small.STL"/>
        </geometry>
        </visual>
        <collision>
            <!-- KFE actuator -->
            <origin rpy="0 0 0" xyz="0.0 0 0"/>
            <geometry>
                <cylinder length="0.1" radius="0.07"/>
            </geometry>
        </collision>
        <inertial>
        <mass value="1.327"/>
        <!-- 0.927 is original mass without additional force sensor -->
        <origin xyz="0 0 -0.06"/>
        <inertia ixx="0.0004403232387" ixy="0" ixz="0" iyy="0.0004403232387" iyz="0" izz="0.0007416"/>
        </inertial>
    </link>

    <joint name="kinova_joint_6" type="revolute">
        <parent link="kinova_link_5"/>
        <child link="kinova_link_6"/>
        <axis xyz="0 0 1"/>
        <limit effort="6.8" lower="-62.8318530718" upper="62.8318530718" velocity="15"/>
        <!-- limit effort also defines torque limit and freeze controller gains -->
        <origin rpy="-1.57079632679 0 3.14159265359" xyz="0 0.10375 0"/>
        <dynamics damping="0.0" friction="0.0"/>
    </joint>

    <link name="kinova_end_effector">
        <!-- Inertial properties and a fixed revolute joint have been added to this link to make it possible to use the gazebo_link_attacher plugin -->
        <!-- Minor collision properties are added to avoid bug/crash when running model in Gazebo -->
        <visual>
        <geometry>
            <box size="0.0001 0.0001 0.0001"/>
        </geometry>
        </visual>
        <collision>
            <!-- KFE actuator -->
            <origin rpy="0 0 0" xyz="0.0 0 0"/>
            <geometry>
                <sphere radius="0.07"/>
            </geometry>
        </collision>
        <inertial>
        <origin rpy="0 0 0" xyz="0.0 0.0 0.0"/>
        <mass value="0.01"/>
        <inertia ixx="0.01" ixy="0" ixz="0" iyy="0.01" iyz="0" izz="0.01"/>
        </inertial>
    </link>

    <joint name="kinova_joint_end_effector" type="fixed">
        <parent link="kinova_link_6"/>
        <child link="kinova_end_effector"/>
        <axis xyz="0 0 0"/>
        <limit effort="2000" lower="0" upper="0" velocity="1"/>
        <origin rpy="3.14159265359 0 0" xyz="0 0 -0.1600"/>
    </joint>
    <!---
    <link name="ball">
        <visual>
            <origin rpy="0 0 0" xyz="0 0 -0.12"/>
            <geometry>
                <sphere radius="0.1"/>
            </geometry>
        </visual>
        <collision>
            <origin rpy="0 0 0" xyz="0 0 -0.12"/>
            <geometry>
                <sphere radius="0.1"/>
            </geometry>
        </collision>
        <inertial>
            <origin rpy="0 0 0" xyz="0 0 -0.12"/>
            <mass value="5"/>
            <inertia ixx="0.002" ixy="0.0" ixz="0" iyy="0.002" iyz="0" izz="0.002"/>
        </inertial>
    </link>

    <joint name="eeToball" type="fixed">
        <parent link="kinova_link_6"/>
        <child link="ball"/>
        <origin xyz="0 0 -0.1"/>
    </joint>
    -->
    
     <?xml version="1.0" ?>
  
</robot>

